Workbook

Sheet DCF
B1: ORGANON & CO. — DCF VALUATION
G3: Historical | J3: Stage 1: Contraction | M3: Stage 2: Stabilisation
G4: FY2024A | H4: FY2025A | J4: FY2026E | K4: FY2027E | M4: FY2028E | N4: FY2029E
B6: REVENUE FORECAST
B7: Growth Rate Assumptions → | J7: -2.0% | K7: -1.5% | M7: +1.0% | N7: +2.0%
B8: Womens Health | G8: 1777 | H8: 1752 | J8: =H8*(1+-0.02) -> 1716.96 | K8: =J8*(1+-0.015) -> 1691.2056 | M8: =K8*(1+0.01) -> 1708.1177 | N8: =M8*(1+0.02) -> 1742.28
B9: Biosimilars | G9: 662 | H9: 691 | J9: =H9*(1+-0.02) -> 677.18 | K9: =J9*(1+-0.015) -> 667.0223 | M9: =K9*(1+0.01) -> 673.69252 | N9: =M9*(1+0.02) -> 687.16637
B10: Established Brands | G10: 3849 | H10: 3691 | J10: =H10*(1+-0.02) -> 3617.18 | K10: =J10*(1+-0.015) -> 3562.9223 | M10: =K10*(1+0.01) -> 3598.5515 | N10: =M10*(1+-0.02) -> 3526.5805
B11: Other / Mfg | G11: 115 | H11: 82 | J11: =H11*(1+-0.02) -> 80.36 | K11: =J11*(1+-0.015) -> 79.1546 | M11: =K11*(1+0.01) -> 79.946146 | N11: =M11*(1+0.02) -> 81.545069
B12: Total Revenue | G12: =G8+G9+G10+G11 -> 6403 | H12: =H8+H9+H10+H11 -> 6216 | J12: =J8+J9+J10+J11 -> 6091.68 | K12: =K8+K9+K10+K11 -> 6000.3048 | M12: =M8+M9+M10+M11 -> 6060.3078 | N12: =N8+N9+N10+N11 -> 6037.5719
B14: EBIT BUILD & NOPAT
B15: Gross Margin % | G15: ='Historical Data'!$F$12 -> 0.57053715 | H15: ='Historical Data'!$F$12 -> 0.57053715 | J15: ='Historical Data'!$F$12 -> 0.57053715 | K15: ='Historical Data'!$F$12 -> 0.57053715 | M15: ='Historical Data'!$F$12 -> 0.57053715 | N15: ='Historical Data'!$F$12 -> 0.57053715
B16: SG&A % Revenue | G16: ='Historical Data'!$F$13 -> 0.28466287 | H16: ='Historical Data'!$F$13 -> 0.28466287 | J16: ='Historical Data'!$F$13 -> 0.28466287 | K16: ='Historical Data'!$F$13 -> 0.28466287 | M16: ='Historical Data'!$F$13 -> 0.28466287 | N16: ='Historical Data'!$F$13 -> 0.28466287
B17: R&D % Revenue | G17: 0.073 | H17: 0.059 | J17: 0.055 | K17: 0.052 | M17: 0.05 | N17: 0.049
B18: Gross Profit | G18: 3715 | H18: 3313 | J18: =J12*J15 -> 3475.5297 | K18: =K12*K15 -> 3423.3968 | M18: =M12*M15 -> 3457.6308 | N18: =N12*N15 -> 3444.6591
B19: Less: SG&A | G19: 1760 | H19: 1721 | J19: =J12*J16 -> 1734.0751 | K19: =K12*K16 -> 1708.064 | M19: =M12*M16 -> 1725.1447 | N19: =N12*N16 -> 1718.6726
B20: Less: R&D | G20: 469 | H20: 366 | J20: =J12*J17 -> 335.0424 | K20: =K12*K17 -> 312.01585 | M20: =M12*M17 -> 303.01539 | N20: =N12*N17 -> 295.84103
B21: Adj. EBIT (Normalized) | G21: 1374 | H21: 824 | J21: =J18-J19-J20 -> 1406.4122 | K21: =K18-K19-K20 -> 1403.3169 | M21: =M18-M19-M20 -> 1429.4707 | N21: =N18-N19-N20 -> 1430.1455
B22: Adj. EBIT Margin % | G22: =G21/G12 -> 0.21458691 | H22: =H21/H12 -> 0.13256113 | J22: =J21/J12 -> 0.23087427 | K22: =K21/K12 -> 0.23387427 | M22: =M21/M12 -> 0.23587427 | N22: =N21/N12 -> 0.23687427
B23: Tax Rate | G23: 0.21 | H23: 0.21 | J23: 0.21 | K23: 0.21 | M23: 0.21 | N23: 0.21
B24: NOPAT = Adj. EBIT × (1 – Tax) | G24: =G21*(1-G23) -> 1085.46 | H24: =H21*(1-H23) -> 650.96 | J24: =J21*(1-J23) -> 1111.0656 | K24: =K21*(1-K23) -> 1108.6204 | M24: =M21*(1-M23) -> 1129.2819 | N24: =N21*(1-N23) -> 1129.8149
B26: REINVESTMENT RATE & FCFF
B27: D&A % Revenue | G27: ='Historical Data'!$F$59 -> 0.046339509 | H27: ='Historical Data'!$F$59 -> 0.046339509 | J27: ='Historical Data'!$F$59 -> 0.046339509 | K27: ='Historical Data'!$F$59 -> 0.046339509 | M27: ='Historical Data'!$F$59 -> 0.046339509 | N27: ='Historical Data'!$F$59 -> 0.046339509
B28: D&A ($mm) | G28: =G12*G27 -> 296.71188 | H28: =H12*H27 -> 288.04639 | J28: =J12*J27 -> 282.28546 | K28: =K12*K27 -> 278.05118 | M28: =M12*M27 -> 280.83169 | N28: =N12*N27 -> 279.77812
B29: CapEx % Revenue | G29: ='Historical Data'!$F$58 -> 0.031156452 | H29: ='Historical Data'!$F$58 -> 0.031156452 | J29: ='Historical Data'!$F$58 -> 0.031156452 | K29: ='Historical Data'!$F$58 -> 0.031156452 | M29: ='Historical Data'!$F$58 -> 0.031156452 | N29: ='Historical Data'!$F$58 -> 0.031156452
B30: Gross CapEx ($mm) | G30: =G12*G29 -> 199.49476 | H30: =H12*H29 -> 193.6685 | J30: =J12*J29 -> 189.79513 | K30: =K12*K29 -> 186.94821 | M30: =M12*M29 -> 188.81769 | N30: =N12*N29 -> 188.10932
B31: Net CapEx = Gross CapEx – D&A | G31: =G30-G28 -> -97.217115 | H31: =H30-H28 -> -94.377883 | J31: =J30-J28 -> -92.490326 | K31: =K30-K28 -> -91.102971 | M31: =M30-M28 -> -92.014 | N31: =N30-N28 -> -91.6688
B32: NWC % Revenue | G32: ='Historical Data'!$F$53 -> 0.28494174 | H32: ='Historical Data'!$F$53 -> 0.28494174 | J32: ='Historical Data'!$F$53 -> 0.28494174 | K32: ='Historical Data'!$F$53 -> 0.28494174 | M32: ='Historical Data'!$F$53 -> 0.28494174 | N32: ='Historical Data'!$F$53 -> 0.28494174
B33: NWC ($mm) | G33: =G12*G32 -> 1824.482 | H33: =H12*H32 -> 1771.1979 | J33: =J12*J32 -> 1735.7739 | K33: =K12*K32 -> 1709.7373 | M33: =M12*M32 -> 1726.8347 | N33: =N12*N32 -> 1720.3563
B34: ΔNWC | H34: =H33-G33 -> -53.284106 | J34: =J33-H33 -> -35.423958 | K34: =K33-J33 -> -26.036609 | M34: =M33-K33 -> 17.097373 | N34: =N33-M33 -> -6.4784081
B35: FCFF = NOPAT +D&A -Capex - Change in NWC | J35: =J24+J28-J30-J34 -> 1238.9799 | K35: =K24+K28-K30-K34 -> 1225.76 | M35: =M24+M28-M30-M34 -> 1204.1985 | N35: =N24+N28-N30-N34 -> 1227.9621
B36: Discount Period (mid-year) | J36: 0.5 | K36: 1.5 | M36: 2.5 | N36: 3.5
B37: Discount Factor = 1/(1+WACC)^n | J37: =1/(1+$G$42)^J36 -> 0.96048362 | K37: =1/(1+$G$42)^K36 -> 0.8860738 | M37: =1/(1+$G$42)^M36 -> 0.81742859 | N37: =1/(1+$G$42)^N36 -> 0.75410141
B38: PV of FCFF | J38: =J35*J37 -> 1190.0199 | K38: =K35*K37 -> 1086.1138 | M38: =M35*M37 -> 984.34627 | N38: =N35*N37 -> 926.00797
B40: TERMINAL VALUE CALCULATION
B41: Terminal Growth Rate (g) | G41: 0.015
B42: WACC | G42: =WACC!J46 -> 0.083977009
B43: FCFF(n+1) = FCFF × (1+g) | G43: =N35*(1+G41) -> 1246.3816
B44: Terminal Value = FCFF(n+1) / (WACC – g) | G44: =G43/(G42-G41) -> 18069.522
B46: ENTERPRISE VALUE → EQUITY VALUE → SHARE PRICE
...

Sheet Accretion Dilution
B1: SUN PHARMA ACQUISITION OF ORGANON — A/D ANALYSIS
B3: PART 1: SOURCES & USES ($mm)
B4: SOURCES | C4: $mm
B5: Sun Cash | C5: 2250
B6: Bridge Financing | C6: 9500
B7: Total Sources | C7: =C5+C6 -> 11750
B9: USES | C9: $mm
B10: Purchase OGN Equity | C10: 3150
B11: Refinance OGN Net Debt | C11: 8070
B12: Transaction Costs | C12: 130
B13: Financing Fees (OID+Arranger) | C13: 400
B14: Total Uses | C14: =C10+C11+C12+C13 -> 11750
B18: PART 2: PRO FORMA INTEREST EXPENSE SCHEDULE
B20: Debt Tranche | C20: Debt ($mm) | D20: Y1 Rate (Bridge) | E20: Y1 Interest | F20: Y2 Rate (Permanent) | G20: Y2 Interest
B21: Bridge (to perm.) | C21: 9500 | D21: 0.0875 | E21: =C21*D21 -> 831.25 | F21: 0.06 | G21: =C21*F21 -> 570 | I21: Note- Year 1 models an immediate, temporary $9.5B Bridge Facility assuming ~8.75% to achieve deal closure. Year 2 assumes a permanent capital market take-out, refinancing the bridge into long-term investment-grade institutional bonds at a normalized 6.00% coupon to secure a structural 275 bps cost-of-capital savings.
B22: Sun Standalone | C22: 700 | D22: 0.07 | E22: =C22*D22 -> 49 | F22: 0.07 | G22: =C22*F22 -> 49
B23: Total Interest Expense | E23: =SUM(E21,E22) -> 880.25 | G23: =SUM(G21,G22) -> 619
B25: PART 3: SYNERGY SCHEDULE
B27: Category | C27: Y1 | D27: Y1 ($mm) | E27: Y2 | F27: Y2 ($mm) | G27: Y3 | H27: Y3 ($mm) | I27: Assumption
B28: Procurement / COGS | C28: 0.005 | D28: =C28*'Historical Data'!$E$10 -> 14.515 | E28: 0.015 | F28: =E28*'Historical Data'!$E$10 -> 43.545 | G28: 0.03 | H28: =G28*'Historical Data'!$E$10 -> 87.09 | I28: Target 3% savings on OGN’s $2.9B COGS using Sun’s supply chain leverage.
B29: SG&A / Headcount | C29: 0.02 | D29: =C29*'Historical Data'!$E$13 -> 34.42 | E29: 0.05 | F29: =E29*'Historical Data'!$E$13 -> 86.05 | G29: 0.08 | H29: =G29*'Historical Data'!$E$13 -> 137.68 | I29: Duplicate functions; regional consolidation; ~8% of OGN SGA
B30: R&D Rationalization | C30: 0.02 | D30: =C30*'Historical Data'!$E$14 -> 7.32 | E30: 0.05 | F30: =E30*'Historical Data'!$E$14 -> 18.3 | G30: 0.08 | H30: =G30*'Historical Data'!$E$14 -> 29.28 | I30: Consolidation of redundant clinical trial sites and cutting overlapping early-stage pipeline programs
B31: Mfg. Network | C31: 0.005 | D31: =C31*'Historical Data'!$E$10 -> 14.515 | E31: 0.01 | F31: =E31*'Historical Data'!$E$10 -> 29.03 | G31: 0.02 | H31: =G31*'Historical Data'!$E$10 -> 58.06 | I31: Offloading Organon’s outsourced production onto Sun’s high-utilization facilities
B32: Revenue (EM channels) | C32: 0.003 | D32: =C32*'Historical Data'!$E$5 -> 18.648 | E32: 0.01 | F32: =E32*'Historical Data'!$E$5 -> 62.16 | G32: 0.02 | H32: =G32*'Historical Data'!$E$5 -> 124.32 | I32: Plugging Organon’s established brands directly into Sun’s dominant India and Emerging Market pharmacy networks.
B33: Revenue (US Specialty) | C33: 0.001 | D33: =C33*'Historical Data'!$E$5 -> 6.216 | E33: 0.003 | F33: =E33*'Historical Data'!$E$5 -> 18.648 | G33: 0.008 | H33: =G33*'Historical Data'!$E$5 -> 49.728 | I33: Cross-selling Sun’s existing dermatology/specialty assets alongside Organon’s demographies.
B34: Total Synergies | D34: =SUM(D28:D33) -> 95.634 | F34: =SUM(F28:F33) -> 257.733 | H34: =SUM(H28:H33) -> 486.158
B35: One-Time Integration Costs | D35: -250 | F35: -150 | H35: 0 | I35: Severance, IT, supply chain; ~0.72x of $486 Million. ($352 Million)
B36: Net Cash Impact | D36: =SUM(D34:D35) -> -154.366 | F36: =SUM(F34:F35) -> 107.733 | H36: =SUM(H34:H35) -> 486.158
B38: PART 4: PRO FORMA P&L
B39: P&L Item | C39: OGN FY2026E | D39: Sun FY2026E | E39: Base Y1 (FY2026E) | F39: Base Y2 (FY2027E) | G39: Up Y1 | H39: Down Y1
B40: Revenue | C40: 6000 | D40: 6750 | I40: Taking as Baseline revenue
B41: + Rev Synergies | C41: 0 | D41: 0 | E41: =SUM(D32:D33) -> 24.864 | F41: =sum(F32,F33) -> 80.808 | G41: 35 | H41: 10
B42: Adj. EBITDA | C42: 1235 | D42: 2000
B43: + Cost Synergies | C43: 0 | D43: 0 | E43: =SUM(D28:D31) -> 70.77 | F43: =SUM(F28:F31) -> 176.925 | G43: 90 | H43: 50
B44: Combined EBITDA | E44: =C42+D42+E43 -> 3305.77 | F44: =C42+D42+F43 -> 3411.925 | G44: =C42+D42+G43 -> 3325 | H44: =C42+D42+H43 -> 3285
B45: Less: D&A | C45: 326 | D45: 310 | E45: =D45+C45 -> 636 | F45: 636 | G45: 636 | H45: 636
B46: Less: Int | E46: =E23 -> 880.25 | F46: =G23 -> 619 | G46: =E23 -> 880.25 | H46: =E23 -> 880.25
B47: PPA Amort (intang.) | E47: -100 | F47: -100 | G47: -100 | H47: -100 | I47: A post-merger accounting adjustment that reflects the gradual, non-cash write-down of Organon's newly revalued intangible assets
B48: Less: One-Time Integr. Cost | E48: =D35 -> -250 | F48: =F35 -> -150 | G48: =D35 -> -250 | H48: =D35 -> -250
B49: EBIT (Pro Forma) | E49: =E44-E45+E47+E48 -> 2319.77 | F49: =F44-F45+F47+F48 -> 2525.925 | G49: =G44-G45+G47+G48 -> 2339 | H49: =H44-H45+H47+H48 -> 2299
...

Sheet Comps Analysis
B1: Relative Valuation Method
B3: Name | C3: Country | D3: Share Price ($) (As of 24/04/26) | E3: Net Debt | F3: Total Equity | G3: Enterprise Value | H3: Revenue | I3: EBIDTA | J3: Net Profit | K3: EV/EBITDA | L3: EV/Revenue | M3: P/E
B5: Organon | C5: USA | D5: ='Beta Regression'!C9 -> 11.26 | E5: 8600 | F5: 3150 | G5: =F5+E5 -> 11750 | H5: 6216 | I5: 1290 | J5: 187 | K5: =G5/I5 -> 9.1085271 | L5: =G5/H5 -> 1.8902831 | M5: =F5/J5 -> 16.84492
B6: Viatris | C6: USA | D6: ='Beta Regression'!G9 -> 14.59 | E6: 11145 | F6: 18551 | G6: =F6+E6 -> 29696 | H6: 14299 | I6: -395 | J6: -3514 | K6: - | L6: =G6/H6 -> 2.0767886 | M6: -
B7: Teva | C7: USA | D7: ='Beta Regression'!K9 -> 30.64 | E7: 11718 | F7: 38729 | G7: =F7+E7 -> 50447 | H7: 17257 | I7: 3141 | J7: 1410 | K7: =G7/I7 -> 16.060809 | L7: =G7/H7 -> 2.9232775 | M7: =F7/J7 -> 27.467376
B8: Hikma | C8: UK | D8: ='Beta Regression'!O9*1.34 -> 1855.9 | E8: 1247 | F8: 3108 | G8: =F8+E8 -> 4355 | H8: 3349 | I8: 845 | J8: 402 | K8: =G8/I8 -> 5.1538462 | L8: =G8/H8 -> 1.3003882 | M8: =F8/J8 -> 7.7313433
B9: Perrigo | C9: Ireland | D9: ='Beta Regression'!S9 -> 11.82 | E9: 3072 | F9: 1606 | G9: =F9+E9 -> 4678 | H9: 4253 | I9: -797 | J9: -1425 | K9: - | L9: =G9/H9 -> 1.0999295 | M9: -
B10: Dr. Reddys | C10: India | D10: ='Beta Regression'!W9 *0.01 -> 13.171 | E10: 0 | F10: 11017 | G10: =F10+E10 -> 11017 | H10: 3359 | I10: 791 | J10: 428 | K10: =G10/I10 -> 13.927939 | L10: =G10/H10 -> 3.2798452 | M10: =F10/J10 -> 25.740654
B11: Cipla | C11: India | D11: ='Beta Regression'!AA9 *0.01 -> 12.95 | E11: 0 | F11: 11660 | G11: =F11+E11 -> 11660 | H11: 2771 | I11: 635 | J11: 387 | K11: =G11/I11 -> 18.362205 | L11: =G11/H11 -> 4.2078672 | M11: =F11/J11 -> 30.129199
B12: Alvotech | C12: Iceland | D12: ='Beta Regression'!AE9 -> 3.38 | E12: 1228 | F12: 1323 | G12: =F12+E12 -> 2551 | H12: 586 | I12: 311 | J12: 27 | K12: =G12/I12 -> 8.2025723 | L12: =G12/H12 -> 4.3532423 | M12: =F12/J12 -> 49
B13: Biocon Bio. | C13: India | D13: ='Beta Regression'!AI9 *0.01 -> 3.4985 | E13: 1301.5 | F13: 7050 | G13: =F13+E13 -> 8351.5 | H13: 1677 | I13: 339 | J13: 38 | K13: =G13/I13 -> 24.635693 | L13: =G13/H13 -> 4.9800239 | M13: =F13/J13 -> 185.52632
B15: Average | K15: =AVERAGE(K5:K13) -> 13.635942 | L15: =AVERAGE(L5:L13) -> 2.9012939 | M15: =AVERAGE(M5:M13) -> 48.919973
B16: Median | K16: =MEDIAN(K5:K13) -> 13.927939 | L16: =MEDIAN(L5:L13) -> 2.9232775 | M16: =MEDIAN(M5:M13) -> 27.467376
B18: Organon Comparable Valuation | K18: EV/EBITDA | L18: EV/Revenue | M18: P/E
B19: Implied Enterprise Value | K19: =K16*I5 -> 17967.042 | L19: =L16*H5 -> 18171.093 | M19: =M16*J5 +E5 -> 13736.399
B20: Implied Market Value | K20: =K19-$E$5 -> 9367.0417 | L20: =L19-$E$5 -> 9571.093 | M20: =M19-$E$5 -> 5136.3993
B21: Implied Share Price | K21: =K20/DCF!$H$30 -> 48.366366 | L21: =L20/DCF!$H$30 -> 49.419977 | M21: =M20/DCF!$H$30 -> 26.521604

Sheet Precedent Transactions
B1: ORGANON — PRECEDENT TRANSACTIONS
B3: CORE COMPARABLE TRANSACTIONS (Cash-Flowing Pharma Carve-Outs & Portfolio Acquisitions)
B5: Acquirer | C5: Target | D5: Date | E5: EV ($mm) | F5: Revenue ($mm) | G5: EBITDA ($mm) | H5: EV / Rev | I5: EV / EBITDA | J5: Category / Strategic Type
B6: Teva | C6: Allergan Generics (Actavis) | D6: 42186 | E6: 40500 | F6: 7800 | G6: 2700 | H6: 5.2 | I6: 15 | J6: Generic Carve-Out
B7: AbbVie | C7: Allergan (incl. WH/aesthetics) | D7: 43617 | E7: 84200 | F7: 15788 | G7: 7760 | H7: 5.3 | I7: 10.9 | J7: Specialty / Diversified Mega-Merger
B8: Bayer | C8: Schering AG | D8: 38777 | E8: 21500 | F8: 6400 | G8: 1450 | H8: 3.4 | I8: 14.8 | J8: Specialty / WH Consolidation
B9: Perrigo | C9: HRA Pharma (OTC WH) | D9: 44440 | E9: 2100 | F9: 290 | G9: 115 | H9: 7.2 | I9: 18.3 | J9: OTC / Consumer Self-Care
B10: Sun Pharma | C10: Ranbaxy Labs | D10: 41730 | E10: 4000 | F10: 2100 | G10: 270 | H10: 1.9 | I10: 14.8 | J10: Generic Platform Consolidation
B11: Hikma | C11: Custopharm (not Columbus) | D11: 44440 | E11: 375 | F11: 80 | G11: 25 | H11: 4.7 | I11: 15 | J11: Sterile Injectables Bolt-On
B12: Bausch Health | C12: Various Rx assets (Right Foods/etc) | D12: 2022 | E12: 170 | F12: 140 | G12: 35 | H12: 1.2 | I12: 4.9 | J12: Mature / Non-Core Asset Carve-Out
B13: Organon | C13: Dermavant Sciences | D13: 45536 | E13: 1200 | F13: 75 | G13: -50 | H13: 16 | I13: NM | J13: Medical Derm / WH Asset Bolt-On
B14: Fresenius Kabi | C14: mAbxience | D14: 44621 | E14: 430 | F14: 100 | G14: 20 | H14: 4.3 | I14: 21.5 | J14: Biosimilar / Biologics Platform
B15: AstraZeneca | C15: Amgen (Biosimilar Rights) | D15: 45261 | E15: 450 | F15: 300 | G15: 90 | H15: 1.5 | I15: 5 | J15: Biosimilar Geographic Asset Swap
B17: TRANSACTION MULTIPLE STATISTICS
C19: EV / Revenue | D19: EV / EBITDA
B20: Minimum | C20: =MIN(H6:H15) -> 1.2 | D20: =MIN(I6:I15) -> 4.9
B21: 25th Pct | C21: =PERCENTILE(H6:H15,0.25) -> 2.275 | D21: =PERCENTILE(I6:I15,0.25) -> 10.9
B22: Median | C22: =MEDIAN(H6:H15) -> 4.5 | D22: =MEDIAN(I6:I15) -> 14.8
B23: Mean | C23: =AVERAGE(H6:H15) -> 5.07 | D23: =AVERAGE(I6:I15) -> 13.355556
B24: 75th Pct | C24: =PERCENTILE(H6:H15,0.75) -> 5.275 | D24: =PERCENTILE(I6:I15,0.75) -> 15
B25: Maximum | C25: =MAX(H6:H15) -> 16 | D25: =MAX(I6:I15) -> 21.5
B28: OGN ACQUISITION MULTIPLE BENCHMARKING
B30: OGN Implied EV / Adj. EBITDA | D30: =11750/'Historical Data'!E26 -> 8.0204778 | E30: Bottom quartile of core comparable universe
B31: OGN Implied EV / Revenue | D31: =11750/'Historical Data'!E5 -> 1.8902831 | E31: Bottom quartile of core comparable universe
B32: vs. Prec. Txn Median (EV/EBITDA) | D32: =1-(D30/D22) -> 0.45807582
B33: CONCLUSION | C33: Sun's $14/share ($11.75B EV) | D33: FAIR / SLIGHTLY BELOW MID

Sheet WACC
B1: Weighted Average Cost of Capital
B3: All figures are in USD unless stated otherwise.
B5: Peer Comps
G6: Debt/ | H6: Debt/ | I6: Levered | J6: Unlevered
B7: Name | C7: Country | D7: Net Debt ($mm) | E7: Total Equity ($mm) | F7: Tax Rate | G7: Equity | H7: Capital | I7: Beta | J7: Beta
B9: Organon | C9: USA | D9: 8600 | E9: 3150 | F9: 0.2 | G9: =D9/E9 -> 2.7301587 | H9: =D9/(D9+E9) -> 0.73191489 | I9: ='Beta Regression'!C4 -> 0.93053539 | J9: =I9/(1+(1-F9)*G9) -> 0.29224192
B10: Viatris | C10: USA | D10: 11145 | E10: 18551 | F10: 0.2 | G10: =D10/E10 -> 0.60077624 | H10: =D10/(D10+E10) -> 0.37530307 | I10: ='Beta Regression'!G4 -> 0.84476294 | J10: =I10/(1+(1-F10)*G10) -> 0.57054638
B11: Teva | C11: USA | D11: 11718 | E11: 38729 | F11: 0.2 | G11: =D11/E11 -> 0.30256397 | H11: =D11/(D11+E11) -> 0.23228339 | I11: ='Beta Regression'!K4 -> 0.90591923 | J11: =I11/(1+(1-F11)*G11) -> 0.72937351
B12: Hikma | C12: UK | D12: 1247 | E12: 3108 | F12: 0.2 | G12: =D12/E12 -> 0.40122265 | H12: =D12/(D12+E12) -> 0.28633754 | I12: ='Beta Regression'!O4 -> 0.37924101 | J12: =I12/(1+(1-F12)*G12) -> 0.28709106
B13: Perrigo | C13: Ireland | D13: 3072 | E13: 1606 | F13: 0.2 | G13: =D13/E13 -> 1.9128269 | H13: =D13/(D13+E13) -> 0.65669089 | I13: ='Beta Regression'!S4 -> 0.81395249 | J13: =I13/(1+(1-F13)*G13) -> 0.3216871
B14: Dr. Reddys | C14: India | D14: 0 | E14: 11017 | F14: 0.2 | G14: =D14/E14 -> 0 | H14: =D14/(D14+E14) -> 0 | I14: ='Beta Regression'!W4 -> 0.32563161 | J14: =I14/(1+(1-F14)*G14) -> 0.32563161
B15: Cipla | C15: India | D15: 0 | E15: 11660 | F15: 0.2 | G15: =D15/E15 -> 0 | H15: =D15/(D15+E15) -> 0 | I15: ='Beta Regression'!AA4 -> 0.3287303 | J15: =I15/(1+(1-F15)*G15) -> 0.3287303
B16: Alvotech | C16: Iceland | D16: 1228 | E16: 1323 | F16: 0.2 | G16: =D16/E16 -> 0.9281935 | H16: =D16/(D16+E16) -> 0.48137985 | I16: ='Beta Regression'!AE4 -> 0.8626935 | J16: =I16/(1+(1-F16)*G16) -> 0.49507396
B17: Biocon Bio. | C17: India | D17: 1301.5 | E17: 7050 | F17: 0.2 | G17: =D17/E17 -> 0.18460993 | H17: =D17/(D17+E17) -> 0.15584027 | I17: ='Beta Regression'!AI4 -> 0.28508403 | J17: =I17/(1+(1-F17)*G17) -> 0.24839856
E19: Average | F19: =AVERAGE(F10:F17) -> 0.2 | G19: =AVERAGE(G10:G17) -> 0.54127415 | H19: =AVERAGE(H10:H17) -> 0.27347938 | I19: =AVERAGE(I10:I17) -> 0.59325189 | J19: =AVERAGE(J10:J17) -> 0.41331656
E20: Median | F20: =MEDIAN(F10:F17) -> 0.2 | G20: =MEDIAN(G10:G17) -> 0.35189331 | H20: =MEDIAN(H10:H17) -> 0.25931046 | I20: =MEDIAN(I10:I17) -> 0.59659675 | J20: =MEDIAN(J10:J17) -> 0.32718095
B23: Cost of Debt | G23: Cost of Equity
B25: Pre-tax Cost of Debt | E25: =0.049 -> 0.049 | G25: Risk Free Rate (10Y US Treasury) | J25: 0.045
B26: Tax Rate | E26: =F20 -> 0.2 | G26: Equity Risk Premium | J26: =6% -> 0.06
B27: After Tax Cost of Debt | E27: =E25*(1-E26) -> 0.0392 | G27: Levered Beta | J27: =I9 -> 0.93053539
G28: Cost of Equity | J28: =J25+(J26*J27) -> 0.10083212
B31: Capital Structure | G31: Levered Beta
D33: Current | E33: Target | G33: Comps Median Unlevered Beta | J33: =J20 -> 0.32718095
B34: Total Debt/Total cap | C34: =D9 -> 8600 | D34: =C34/C36 -> 0.73191489 | E34: =H19 -> 0.27347938 | G34: Target Debt/ Equity | J34: =G20 -> 0.35189331
B35: Equity/Total cap | C35: =E9 -> 3150 | D35: =C35/C36 -> 0.26808511 | E35: =E36-E34 -> 0.72652062 | G35: Tax Rate | J35: =E26 -> 0.2
B36: Total Capitalization | C36: =SUM(C34:C35) -> 11750 | D36: =D34+D35 -> 1 | E36: =D36 -> 1 | G36: Levered Beta | J36: =J33*(1+(1-J34)*J35) -> 0.36959058
B38: Debt / Equity | D38: =D34/D35 -> 2.7301587 | E38: =E34/E35 -> 0.37642342 | G38: Weighted Average Cost of Capital
B40: Unlevered Beta = Levered Beta/(1+(1-Tax Rate) x Debt/Equity) | G40: Cost of Equity | J40: =J28 -> 0.10083212
B41: Levered Beta = Unlevered Beta/(1+(1-Tax Rate) x Debt/Equity) | G41: Equity Weight | J41: =E35 -> 0.72652062
G43: Cost of Debt | J43: =E27 -> 0.0392
G44: Debt Weight | J44: =E34 -> 0.27347938
G46: WACC | J46: =(J40*J41)+(J43*J44) -> 0.083977009

Sheet Beta Regression
B1: Regression Beta- 2 years daily
B3: Levered raw beta | C3: =SLOPE(D9:D500,$AN9:$AN500) -> 0.90738052 | E3: =MIN(C9:C260) -> 5.7 | F3: Levered raw beta | G3: =SLOPE(H9:H500,$AN9:$AN500) -> 0.79301726 | J3: Levered raw beta | K3: =SLOPE(L9:L500,$AN9:$AN500) -> 0.87455897 | N3: Levered raw beta | O3: =SLOPE(P9:P500,$AN9:$AN500) -> 0.17232134 | R3: Levered raw beta | S3: =SLOPE(T9:T500,$AN9:$AN500) -> 0.75193665 | V3: Levered raw beta | W3: =SLOPE(X9:X500,$AN9:$AN500) -> 0.10084214 | Z3: Levered raw beta | AA3: =SLOPE(AB9:AB500,$AN9:$AN500) -> 0.10497373 | AD3: Levered raw beta | AE3: =SLOPE(AF9:AF500,$AN9:$AN500) -> 0.81692466 | AH3: Levered raw beta | AI3: =SLOPE(AJ9:AJ500,$AN9:$AN500) -> 0.046778712
B4: Adjusted beta | C4: =(0.75*C3)+(0.25*1) -> 0.93053539 | E4: =MAX(C9:C260) -> 13.16 | F4: Adjusted beta | G4: =(0.75*G3)+(0.25*1) -> 0.84476294 | J4: Adjusted beta | K4: =(0.75*K3)+(0.25*1) -> 0.90591923 | N4: Adjusted beta | O4: =(0.75*O3)+(0.25*1) -> 0.37924101 | R4: Adjusted beta | S4: =(0.75*S3)+(0.25*1) -> 0.81395249 | V4: Adjusted beta | W4: =(0.75*W3)+(0.25*1) -> 0.32563161 | Z4: Adjusted beta | AA4: =(0.75*AA3)+(0.25*1) -> 0.3287303 | AD4: Adjusted beta | AE4: =(0.75*AE3)+(0.25*1) -> 0.8626935 | AH4: Adjusted beta | AI4: =(0.75*AI3)+(0.25*1) -> 0.28508403
B6: Organon | F6: Viatris | J6: Teva | N6: Hikma | R6: Perrigo | V6: Dr Reddy | Z6: Cipla | AD6: Alvotech | AH6: Biocon | AL6: S&P 500
B8: Date | C8: Closing Price | D8: Return | F8: Date | G8: Closing Price | H8: Return | J8: Date | K8: Closing Price | L8: Return | N8: Date | O8: Closing Price | P8: Return | R8: Date | S8: Closing Price | T8: Return | V8: Date | W8: Closing Price | X8: Return | Z8: Date | AA8: Closing Price | AB8: Return | AD8: Date | AE8: Closing Price | AF8: Return | AH8: Date | AI8: Closing Price | AJ8: Return | AL8: Date | AM8: Closing Price | AN8: Return
B9: 46136 | C9: 11.26 | D9: =(C9-C10)/C10 -> 0.30930233 | F9: 46136 | G9: 14.59 | H9: =(G9-G10)/G10 -> -0.010847458 | J9: 46136 | K9: 30.64 | L9: =(K9-K10)/K10 -> -0.018263377 | N9: 46136 | O9: 1385 | P9: =(O9-O10)/O10 -> -0.012477718 | R9: 46136 | S9: 11.82 | T9: =(S9-S10)/S10 -> 0.011120616 | V9: 46136 | W9: 1317.1 | X9: =(W9-W10)/W10 -> -0.010443276 | Z9: 46136 | AA9: 1295 | AB9: =(AA9-AA10)/AA10 -> -0.0083467341 | AD9: 46136 | AE9: 3.38 | AF9: =(AE9-AE10)/AE10 -> 0 | AH9: 46136 | AI9: 349.85 | AJ9: =(AI9-AI10)/AI10 -> -0.022765363 | AL9: 46136 | AM9: 7165.08 | AN9: =(AM9-AM10)/AM10 -> 0.007973665
B10: 46135 | C10: 8.6 | D10: =(C10-C11)/C11 -> -0.059080963 | F10: 46135 | G10: 14.75 | H10: =(G10-G11)/G11 -> 0.01584022 | J10: 46135 | K10: 31.21 | L10: =(K10-K11)/K11 -> -0.0003203075 | N10: 46135 | O10: 1402.5 | P10: =(O10-O11)/O11 -> 0.060892587 | R10: 46135 | S10: 11.69 | T10: =(S10-S11)/S11 -> -0.010998308 | V10: 46135 | W10: 1331 | X10: =(W10-W11)/W11 -> 0.093672966 | Z10: 46135 | AA10: 1305.9 | AB10: =(AA10-AA11)/AA11 -> 0.056297015 | AD10: 46135 | AE10: 3.38 | AF10: =(AE10-AE11)/AE11 -> -0.034285714 | AH10: 46135 | AI10: 358 | AJ10: =(AI10-AI11)/AI11 -> 0.00055897149 | AL10: 46135 | AM10: 7108.4 | AN10: =(AM10-AM11)/AM11 -> -0.0041328682
B11: 46134 | C11: 9.14 | D11: =(C11-C12)/C12 -> 0.033936652 | F11: 46134 | G11: 14.52 | H11: =(G11-G12)/G12 -> -0.014256619 | J11: 46134 | K11: 31.22 | L11: =(K11-K12)/K12 -> -0.0022371365 | N11: 46134 | O11: 1322 | P11: =(O11-O12)/O12 -> -0.019287834 | R11: 46134 | S11: 11.82 | T11: =(S11-S12)/S12 -> 0.0076726343 | V11: 46134 | W11: 1217 | X11: =(W11-W12)/W12 -> -0.0029493692 | Z11: 46134 | AA11: 1236.3 | AB11: =(AA11-AA12)/AA12 -> 0.0030831643 | AD11: 46134 | AE11: 3.5 | AF11: =(AE11-AE12)/AE12 -> -0.0028490028 | AH11: 46134 | AI11: 357.8 | AJ11: =(AI11-AI12)/AI12 -> -0.010235131 | AL11: 46134 | AM11: 7137.9 | AN11: =(AM11-AM12)/AM12 -> 0.010460064
B12: 46133 | C12: 8.84 | D12: =(C12-C13)/C13 -> -0.045356371 | F12: 46133 | G12: 14.73 | H12: =(G12-G13)/G13 -> -0.0094149294 | J12: 46133 | K12: 31.29 | L12: =(K12-K13)/K13 -> -0.022798251 | N12: 46133 | O12: 1348 | P12: =(O12-O13)/O13 -> -0.021415608 | R12: 46133 | S12: 11.73 | T12: =(S12-S13)/S13 -> -0.025747508 | V12: 46133 | W12: 1220.6 | X12: =(W12-W13)/W13 -> -0.0097355184 | Z12: 46133 | AA12: 1232.5 | AB12: =(AA12-AA13)/AA13 -> 0.0024400163 | AD12: 46133 | AE12: 3.51 | AF12: =(AE12-AE13)/AE13 -> -0.03038674 | AH12: 46133 | AI12: 361.5 | AJ12: =(AI12-AI13)/AI13 -> 0.0068235622 | AL12: 46133 | AM12: 7064.01 | AN12: =(AM12-AM13)/AM13 -> -0.0063481659
B13: 46132 | C13: 9.26 | D13: =(C13-C14)/C14 -> -0.051229508 | F13: 46132 | G13: 14.87 | H13: =(G13-G14)/G14 -> 0.012942779 | J13: 46132 | K13: 32.02 | L13: =(K13-K14)/K14 -> -0.011728395 | N13: 46132 | O13: 1377.5 | P13: =(O13-O14)/O14 -> -0.0010877447 | R13: 46132 | S13: 12.04 | T13: =(S13-S14)/S14 -> 0.020338983 | V13: 46132 | W13: 1232.6 | X13: =(W13-W14)/W14 -> -0.0025086995 | Z13: 46132 | AA13: 1229.5 | AB13: =(AA13-AA14)/AA14 -> -0.0091070277 | AD13: 46132 | AE13: 3.62 | AF13: =(AE13-AE14)/AE14 -> 0.0027700831 | AH13: 46132 | AI13: 359.05 | AJ13: =(AI13-AI14)/AI14 -> 0.0026528903 | AL13: 46132 | AM13: 7109.14 | AN13: =(AM13-AM14)/AM14 -> -0.0023743836
B14: 46129 | C14: 9.76 | D14: =(C14-C15)/C15 -> 0.046087889 | F14: 46129 | G14: 14.68 | H14: =(G14-G15)/G15 -> 0.047822984 | J14: 46129 | K14: 32.4 | L14: =(K14-K15)/K15 -> 0.03646833 | N14: 46129 | O14: 1379 | P14: =(O14-O15)/O15 -> 0.026805659 | R14: 46129 | S14: 11.8 | T14: =(S14-S15)/S15 -> 0.033274956 | V14: 46129 | W14: 1235.7 | X14: =(W14-W15)/W15 -> 0.011707876 | Z14: 46129 | AA14: 1240.8 | AB14: =(AA14-AA15)/AA15 -> 0.0083705811 | AD14: 46129 | AE14: 3.61 | AF14: =(AE14-AE15)/AE15 -> -0.0027624309 | AH14: 46129 | AI14: 358.1 | AJ14: =(AI14-AI15)/AI15 -> 0.020955096 | AL14: 46129 | AM14: 7126.06 | AN14: =(AM14-AM15)/AM15 -> 0.012040424
B15: 46128 | C15: 9.33 | D15: =(C15-C16)/C16 -> 0.013029316 | F15: 46128 | G15: 14.01 | H15: =(G15-G16)/G16 -> 0.010822511 | J15: 46128 | K15: 31.26 | L15: =(K15-K16)/K16 -> -0.011072445 | N15: 46128 | O15: 1343 | P15: =(O15-O16)/O16 -> -0.0037091988 | R15: 46128 | S15: 11.42 | T15: =(S15-S16)/S16 -> 0.00087642419 | V15: 46128 | W15: 1221.4 | X15: =(W15-W16)/W16 -> 0.0029561504 | Z15: 46128 | AA15: 1230.5 | AB15: =(AA15-AA16)/AA16 -> 0.0028524857 | AD15: 46128 | AE15: 3.62 | AF15: =(AE15-AE16)/AE16 -> -0.010928962 | AH15: 46128 | AI15: 350.75 | AJ15: =(AI15-AI16)/AI16 -> 0.0011417154 | AL15: 46128 | AM15: 7041.28 | AN15: =(AM15-AM16)/AM16 -> 0.0026100143
B16: 46127 | C16: 9.21 | D16: =(C16-C17)/C17 -> 0.05862069 | F16: 46127 | G16: 13.86 | H16: =(G16-G17)/G17 -> -0.0035945363 | J16: 46127 | K16: 31.61 | L16: =(K16-K17)/K17 -> -0.0050361977 | N16: 46127 | O16: 1348 | P16: =(O16-O17)/O17 -> 0.0059701493 | R16: 46127 | S16: 11.41 | T16: =(S16-S17)/S17 -> -0.0052310375 | V16: 46127 | W16: 1217.8 | X16: =(W16-W17)/W17 -> -0.005877551 | Z16: 46127 | AA16: 1227 | AB16: =(AA16-AA17)/AA17 -> 0.0069757899 | AD16: 46127 | AE16: 3.66 | AF16: =(AE16-AE17)/AE17 -> 0.036827195 | AH16: 46127 | AI16: 350.35 | AJ16: =(AI16-AI17)/AI17 -> 0.0082014388 | AL16: 46127 | AM16: 7022.95 | AN16: =(AM16-AM17)/AM17 -> 0.0079757384
B17: 46126 | C17: 8.7 | D17: =(C17-C18)/C18 -> 0.018735363 | F17: 46126 | G17: 13.91 | H17: =(G17-G18)/G18 -> 0.0057845264 | J17: 46126 | K17: 31.77 | L17: =(K17-K18)/K18 -> 0.019903692 | N17: 46126 | O17: 1340 | P17: =(O17-O18)/O18 -> 0.013999243 | R17: 46126 | S17: 11.47 | T17: =(S17-S18)/S18 -> 0.014146773 | V17: 46126 | W17: 1225 | X17: =(W17-W18)/W18 -> -0.0088194838 | Z17: 46126 | AA17: 1218.5 | AB17: =(AA17-AA18)/AA18 -> 0.0061101478 | AD17: 46126 | AE17: 3.53 | AF17: =(AE17-AE18)/AE18 -> -0.04851752 | AH17: 46126 | AI17: 347.5 | AJ17: =(AI17-AI18)/AI18 -> 0.0072463768 | AL17: 46126 | AM17: 6967.38 | AN17: =(AM17-AM18)/AM18 -> 0.011782918
B18: 46125 | C18: 8.54 | D18: =(C18-C19)/C19 -> -0.032842582 | F18: 46125 | G18: 13.83 | H18: =(G18-G19)/G19 -> 0.026726058 | J18: 46125 | K18: 31.15 | L18: =(K18-K19)/K19 -> 0.010707333 | N18: 46125 | O18: 1321.5 | P18: =(O18-O19)/O19 -> -0.00037821483 | R18: 46125 | S18: 11.31 | T18: =(S18-S19)/S19 -> 0.041436464 | V18: 46125 | W18: 1235.9 | X18: =(W18-W19)/W19 -> 0.0030027593 | Z18: 46125 | AA18: 1211.1 | AB18: =(AA18-AA19)/AA19 -> -0.014965433 | AD18: 46125 | AE18: 3.71 | AF18: =(AE18-AE19)/AE19 -> 0.024861878 | AH18: 46125 | AI18: 345 | AJ18: =(AI18-AI19)/AI19 -> -0.010327022 | AL18: 46125 | AM18: 6886.24 | AN18: =(AM18-AM19)/AM19 -> 0.010173261
B19: 46122 | C19: 8.83 | D19: =(C19-C20)/C20 -> 0.27785818 | F19: 46122 | G19: 13.47 | H19: =(G19-G20)/G20 -> -0.010286554 | J19: 46122 | K19: 30.82 | L19: =(K19-K20)/K20 -> -0.0045219638 | N19: 46122 | O19: 1322 | P19: =(O19-O20)/O20 -> -0.003392386 | R19: 46122 | S19: 10.86 | T19: =(S19-S20)/S20 -> 0.024528302 | V19: 46122 | W19: 1232.2 | X19: =(W19-W20)/W20 -> 0.016750557 | Z19: 46122 | AA19: 1229.5 | AB19: =(AA19-AA20)/AA20 -> 0.0041653055 | AD19: 46122 | AE19: 3.62 | AF19: =(AE19-AE20)/AE20 -> 0.0055555556 | AH19: 46122 | AI19: 348.6 | AJ19: =(AI19-AI20)/AI20 -> 0.0083887764 | AL19: 46122 | AM19: 6816.89 | AN19: =(AM19-AM20)/AM20 -> -0.0011385183
B20: 46121 | C20: 6.91 | D20: =(C20-C21)/C21 -> 0.17918089 | F20: 46121 | G20: 13.61 | H20: =(G20-G21)/G21 -> 0.0029476787 | J20: 46121 | K20: 30.96 | L20: =(K20-K21)/K21 -> 0.014416776 | N20: 46121 | O20: 1326.5 | P20: =(O20-O21)/O21 -> 0.0095129376 | R20: 46121 | S20: 10.6 | T20: =(S20-S21)/S21 -> -0.021237304 | V20: 46121 | W20: 1211.9 | X20: =(W20-W21)/W21 -> 0.017206648 | Z20: 46121 | AA20: 1224.4 | AB20: =(AA20-AA21)/AA21 -> 0.0069907065 | AD20: 46121 | AE20: 3.6 | AF20: =(AE20-AE21)/AE21 -> 0.0055865922 | AH20: 46121 | AI20: 345.7 | AJ20: =(AI20-AI21)/AI21 -> -0.011720983 | AL20: 46121 | AM20: 6824.66 | AN20: =(AM20-AM21)/AM21 -> 0.0061700092
... B500: 45407 | C500: 18.42 | D500: =(C500-C501)/C501 -> -0.015499733 | F500: 45407 | G500: 11.47 | H500: =(G500-G501)/G501 -> -0.0069264069 | J500: 45407 | K500: 13.25 | L500: =(K500-K501)/K501 -> 0.018447348 | N500: 45407 | O500: 1854 | P500: =(O500-O501)/O501 -> 0.022614451 | R500: 45407 | S500: 31.27 | T500: =(S500-S501)/S501 -> 0.0012808197 | V500: 45407 | W500: 1243.75 | X500: =(W500-W501)/W501 -> 0.045027559 | Z500: 45407 | AA500: 1406.2 | AB500: =(AA500-AA501)/AA501 -> 0.0057216421 | AD500: 45407 | AE500: 13.65 | AF500: =(AE500-AE501)/AE501 -> 0.0081240768 | AH500: 45407 | AI500: 291.65 | AJ500: =(AI500-AI501)/AI501 -> 0.0070787293 | AL500: 45407 | AM500: 5048.42 | AN500: =(AM500-AM501)/AM501 -> -0.0045764379
B501: 45406 | C501: 18.71 | F501: 45406 | G501: 11.55 | J501: 45406 | K501: 13.01 | N501: 45406 | O501: 1813 | R501: 45406 | S501: 31.23 | V501: 45406 | W501: 1190.16 | Z501: 45406 | AA501: 1398.2 | AD501: 45406 | AE501: 13.54 | AH501: 45406 | AI501: 289.6 | AL501: 45406 | AM501: 5071.63

Sheet Historical Data
B1: ORGANON & CO. — HISTORICAL FINANCIALS & REINVESTMENT ANALYSIS
B2: ($ in Millions | Source: OGN 10-K FY2025, FY2024, FY2023)
B3: Line Item | C3: FY2023A | D3: FY2024A | E3: FY2025A | F3: 3yr Avg/ Note
B4: INCOME STATEMENT
B5: Revenue | C5: 6263 | D5: 6403 | E5: 6216
B6: Womens Health | C6: 1702 | D6: 1777 | E6: 1752
B7: Biosimilars | C7: 593 | D7: 662 | E7: 691
B8: Established Brands | C8: 3847 | D8: 3849 | E8: 3691
B9: Other / Mfg | C9: 121 | D9: 115 | E9: 82
B10: Cost of Sales | C10: 2515 | D10: 2688 | E10: 2903
B11: Gross Profit | C11: =C5-C10 -> 3748 | D11: =D5-D10 -> 3715 | E11: =E5-E10 -> 3313
B12: Gross Margin % | C12: =C11/C5 -> 0.59843525 | D12: =D11/D5 -> 0.58019678 | E12: =E11/E5 -> 0.53297941 | F12: =AVERAGE(C12:E12) -> 0.57053715
B13: SGA | C13: 1893 | D13: 1760 | E13: 1721 | F13: =((C13/$C$5)+(D13/$D$5)+(E13/$E$5))/3 -> 0.28466287
B14: RD | C14: 528 | D14: 469 | E14: 366
B15: IPR&D / Milestones | C15: 8 | D15: 81 | E15: 6 | F15: Non-recurring
B16: Goodwill Impairment | C16: 0 | D16: 0 | E16: 301 | F16: Non-recurring non-cash
B17: Restructuring | C17: 62 | D17: 31 | E17: 95 | F17: Non-recurring
B18: EBIT | C18: =C11-C13-C14-C15-C16-C17 -> 1257 | D18: =D11-D13-D14-D15-D16-D17 -> 1374 | E18: =E11-E13-E14-E15-E16-E17 -> 824 | F18: =AVERAGE(C18:E18) -> 1151.6667
B19: + DA (Depr. + Amort.) | C19: 236 | D19: 277 | E19: 361
B20: EBITDA | C20: =C18+C19 -> 1493 | D20: =D18+D19 -> 1651 | E20: =E18+E19 -> 1185
B21: + Goodwill Impairment | C21: 0 | D21: 0 | E21: 301 | F21: Add back non-cash
B22: + Restructuring | C22: 62 | D22: 31 | E22: 95 | F22: Add back non-recurring
B23: + IPR&D / Milestones | C23: 8 | D23: 81 | E23: 6 | F23: Add back
B24: - Inventory FV Charge | C24: 0 | D24: 0 | E24: -49 | F24: Dermavant PPA; one-time
B25: - Debt Extinguish. Gain | C25: 0 | D25: 0 | E25: -73 | F25: Non-cash gain on repurchase
B26: Adj. EBITDA | C26: =C20+C21+C22+C23+C24+C25 -> 1563 | D26: =D20+D21+D22+D23+D24+D25 -> 1763 | E26: =E20+E21+E22+E23+E24+E25 -> 1465 | F26: =AVERAGE(C26:E26) -> 1597
B27: Adj. EBITDA Margin % | C27: =C26/C5 -> 0.24956091 | D27: =D26/D5 -> 0.27533968 | E27: =E26/E5 -> 0.23568211 | F27: =AVERAGE(C27:E27) -> 0.25352757
B28: Interest Expense | C28: 527 | D28: 520 | E28: 504 | F28: Wtd avg rate 4.9% on ~$8.6B debt
B29: Other Income / (Expense) | C29: -15 | D29: -21 | E29: 119
B30: Income Before Tax | C30: 673 | D30: 807 | E30: 425
B31: Tax (Expense) / Benefit | C31: 350 | D31: 57 | E31: -238
B32: Net Income | C32: 1023 | D32: 864 | E32: 187
B33: Diluted EPS ($) | C33: =(C32/256.3) -> 3.9914163 | D33: =(D32/259.2) -> 3.3333333 | E33: =(E32/260.8) -> 0.71702454
B35: BALANCE SHEET SNAPSHOT
B36: Cash & Equivalents | D36: 675 | E36: 574
B37: Net PP&E | D37: 1168 | E37: 1303
B38: Intangibles (net) | D38: 1414 | E38: 1130
B39: Goodwill | D39: 4680 | E39: 4153
B40: Total Assets | D40: 13101 | E40: 12867
B41: Gross Debt | D41: 8880 | E41: 8644
...
